<mujoco>
    <default>
      <default class="visual">
        <geom group="2" type="mesh"/>
      </default>
      <default class="collision">
        <geom group="3" type="mesh"/>
      </default>
    </default>
  
    <extension>
      <plugin plugin="mujoco.sdf.sdflib">
        <instance name="sdf1">
          <config key="aabb" value="0"/>
        </instance>
      </plugin>
      <plugin plugin="mujoco.sdf.sdflib">
        <instance name="sdf2">
          <config key="aabb" value="0"/>
        </instance>
      </plugin>
    </extension>
  
    <asset>
      <!-- <texture name="ball_pattern" type="2d" file="ball_texture.jpg"/>
      <material name="pink_ball" texture="ball_pattern"/> -->
  
      <mesh name="table" file="asset/foosball_table/foosball_table.obj"> <!-- already scaled down (0.1)-->
        <plugin instance="sdf1"/>
      </mesh>

      <mesh name="guy" file="asset/foosman/mesh_down_foosman.obj" scale='0.1 0.1 0.1' >
          <plugin instance="sdf2"/>
      </mesh>

      <mesh name="handle" file="asset/handle/foosball_handle.obj" scale='0.1 0.1 0.1'/>
    </asset>
  
    <option sdf_iterations="20" sdf_initpoints="40"  >
      <flag contact="enable" />
    </option>
    
    <visual>
      <map force="1000"/>
    </visual>

    <statistic meansize="0.2"/>

    <default>
      <geom solref="0.004 1" solimp=".99 .99 .00001"  condim="4"/>
    </default>
  
    <include file="foosball_scene.xml"/>

    <worldbody>
      <!-- TABLE-->
      <body name="table" euler="90 90 0" pos="0 0 0">
        <!-- <inertial pos="-0.000002765 0.000000008 1.053097" quat="1 0 0 0" mass="54.82168339136806" 
                  diaginertia="7049.04002 1362.00289 8372.77663"/> -->
        <geom type="sdf" name="table" mesh="table" rgba='1.0 1.0 1.0 1' group="2">
          <plugin instance="sdf1"/>
        </geom>
      </body>


    <!-- Yellow Player--><!-- Yellow Player--><!-- Yellow Player--><!-- Yellow Player-->
      <!-- Yellow goalie Rod-->
      <body name="y_goal_rod" pos="6.902 -52.5 7.75" euler="0 90 0">
        <joint name="y_goal_linear" type="slide" axis="0 0 1" range="-300 300"/>
        <joint name="y_goal_rotation" type="hinge" axis="0 0 1" range="-180.0 180.0"/>
        <inertial pos="0 0 0" mass="1.20268" diaginertia="111.19898539 111.2074505 0.05583827"/>
        <!-- Yellow goalkeeper Aluminum Rod -->
        <geom name="y_goal_rod" type="cylinder" size="0.78 52.7" pos="0 0 0" rgba="0.8 0.8 0.8 1"/>
        <!-- Yellow Handle -->
        <body name="y_goal_rod_handle" pos="0 0 50.5" euler="180 0 0">
          <geom type="mesh" mesh="handle" mass='0.01' rgba='0.7 0.7 0.0 1' />
        </body>
        <!-- Rubber Pad-->
        <body name="y_goal_rod_r_rubber" pos="0 0 -30.435" euler="0 0 90">
          <inertial pos="0 0 0" quat="1 0 0 0" mass="0.05" diaginertia="0.00179 0.00179 0.00306"/>
          <geom name="y_goal_rod_r_rubber" type="cylinder" friction="0.1" size="1.5875 1.27" pos="0 0 0" rgba="0.0 0.0 0.0 1"/>
        </body>
        <body name="y_goal_rod_l_rubber" pos="0 0 16.63" euler="0 0 90">
          <inertial pos="0 0 0" quat="1 0 0 0" mass="0.05" diaginertia="0.00179 0.00179 0.00306"/>
          <geom name="y_goal_rod_l_rubber" type="cylinder" friction="0.1" size="1.5875 1.27" pos="0 0 0" rgba="0.0 0.0 0.0 1"/>
        </body>
        <!-- 3 Yellow Players -->
        <body name="y_goal_guy1" pos="1.49 -0.05 -27.578" euler="180 -90 0">
          <geom type="sdf" name="y_goal_guy1" mesh="guy" mass='0.07' rgba="0.95 0.95 0.0 1">
              <plugin instance="sdf2"/>
          </geom>
        </body>
        <body name="y_goal_guy2" pos="1.49 -0.05 -6.902" euler="180 -90 0">
          <geom type="sdf" name="y_goal_guy2" mesh="guy" mass='0.07' rgba="0.95 0.95 0.0 1">
              <plugin instance="sdf2"/>
          </geom>
        </body>
        <body name="y_goal_guy3" pos="1.49 -0.05 13.773" euler="180 -90 0">
          <geom type="sdf" name="y_goal_guy3" mesh="guy" mass='0.07' rgba="0.95 0.95 0.0 1">
              <plugin instance="sdf2"/>
          </geom>
        </body>
      </body>
    
      <!-- Yellow defender Rod-->
      <body name="y_def_rod" pos="6.6715 -37.5 7.75" euler="0 90 0">
        <joint name="y_def_linear" type="slide" axis="0 0 1" range="-250 250"/>
        <joint name="y_def_rotation" type="hinge" axis="0 0 1" range="-180.0 180.0"/>
        <inertial pos="0 0 0" mass="1.40207" diaginertia="176.18752095 176.18752095 0.05522986"/>
        <!-- Yellow defender Aluminum Rod -->
        <geom name="y_def_rod" type="cylinder" size="0.78 61.4365" pos="0 0 0" rgba="0.8 0.8 0.8 1"/>
        <!-- Yellow Handle --> 
        <body name="y_def_rod_handle" pos="0 0 58.644" euler="180 0 0">
          <geom type="mesh" mesh="handle" mass='0.01' rgba='0.7 0.7 0.0 1' />
        </body>
        <!-- Rubber Pad-->
        <body name="y_def_rod_r_rubber" pos="0 0 -21.466" euler="0 0 90">
          <inertial pos="0 0 0" quat="1 0 0 0" mass="0.05" diaginertia="0.00179 0.00179 0.00306"/>
          <geom name="y_def_rod_r_rubber" type="cylinder" friction="0.1" size="1.5875 1.27" pos="0 0 0" rgba="0.0 0.0 0.0 1"/>
        </body>
        <body name="y_def_rod_l_rubber" pos="0 0 8.124" euler="0 0 90">
          <inertial pos="0 0 0" quat="1 0 0 0" mass="0.05" diaginertia="0.00179 0.00179 0.00306"/>
          <geom name="y_def_rod_l_rubber" type="cylinder" friction="0.1" size="1.5875 1.27" pos="0 0 0" rgba="0.0 0.0 0.0 1"/>
        </body>
        <!-- 2 Yellow Players -->
        <body name="y_def_guy1" pos="1.49 -0.05 -18.609" euler="180 -90 0">
          <geom type="sdf" name="y_def_guy1" mesh="guy" mass='0.07' rgba="0.95 0.95 0.0 1">
              <plugin instance="sdf2"/>
          </geom>
        </body>
        <body name="y_def_guy2" pos="1.49 -0.05 5.266" euler="180 -90 0">
          <geom type="sdf" name="y_def_guy2" mesh="guy" mass='0.07' rgba="0.95 0.95 0.0 1">
              <plugin instance="sdf2"/>
          </geom>
        </body>
      </body>

      <!-- Yellow Midfield Rod-->
      <body name="y_mid_rod" pos="6.887 -7.5 7.75" euler="0 90 0">
        <joint name="y_mid_linear" type="slide" axis="0 0 1" range="-500 500"/>
        <joint name="y_mid_rotation" type="hinge" axis="0 0 1" range="-180.0 180.0"/>
        <inertial pos="0 0 0" mass="1.1264" diaginertia="91.364224 91.364224 0.044368"/>
        <!-- Yellow Midfield Aluminum Rod -->
        <geom type="cylinder" size="0.78 49.365" pos="0 0 0" rgba="0.8 0.8 0.8 1"/>
        <!-- Yellow Handle -->
        <body name="y_mid_rod_handle" pos="0 0 46.34" euler="180 0 0">
          <geom type="mesh" mesh="handle" mass='0.01' rgba='0.7 0.7 0.0 1' />
        </body>
        <!-- Rubber Pad-->
        <body name="y_mid_rod_r_rubber" pos="0 0 -33.695" euler="0 0 90">
          <inertial pos="0 0 0" quat="1 0 0 0" mass="0.05" diaginertia="0.00179 0.00179 0.00306"/>
          <geom name="y_mid_rod_r_rubber" type="cylinder" friction="0.1" size="1.5875 1.27" pos="0 0 0" rgba="0.0 0.0 0.0 1"/>
        </body>
        <body name="y_mid_rod_l_rubber" pos="0 0 19.92" euler="0 0 90">
          <inertial pos="0 0 0" quat="1 0 0 0" mass="0.05" diaginertia="0.00179 0.00179 0.00306"/>
          <geom name="y_mid_rod_l_rubber" type="cylinder" friction="0.1" size="1.5875 1.27" pos="0 0 0" rgba="0.0 0.0 0.0 1"/>
        </body>
        <!-- 5 Yellow Players -->
        <body name="y_mid_guy1" pos="1.49 -0.05 -30.837" euler="180 -90 0">
          <geom type="sdf" name="y_mid_guy1" mesh="guy" mass="0.07" rgba="0.95 0.95 0.0 1">
              <plugin instance="sdf2"/>
          </geom>
        </body>
        <body name="y_mid_guy2" pos="1.49 -0.05 -18.862" euler="180 -90 0">
          <geom type="sdf" name="y_mid_guy2" mesh="guy" mass="0.07" rgba="0.95 0.95 0.0 1">
              <plugin instance="sdf2"/>
          </geom>
        </body>
        <body name="y_mid_guy3" pos="1.49 -0.05 -6.887" euler="180 -90 0">
          <geom type="sdf" name="y_mid_guy3" mesh="guy" mass="0.07" rgba="0.95 0.95 0.0 1">
              <plugin instance="sdf2"/>
          </geom>
        </body>
        <body name="y_mid_guy4" pos="1.49 -0.05 5.088" euler="180 -90 0">
          <geom type="sdf" name="y_mid_guy4" mesh="guy" mass="0.07" rgba="0.95 0.95 0.0 1">
              <plugin instance="sdf2"/>
          </geom>
        </body>
        <body name="y_mid_guy5" pos="1.49 -0.05 17.063" euler="180 -90 0">
          <geom type="sdf" name="y_mid_guy5" mesh="guy" mass="0.07" rgba="0.95 0.95 0.0 1">
              <plugin instance="sdf2"/>
          </geom>
        </body>
      </body>

      <!-- Yellow attacker Rod-->
      <body name="y_attack_rod" pos="6.784 22.5 7.75" euler="0 90 0">
        <joint name="y_attack_linear" type="slide" axis="0 0 1" range="-300 300"/>
        <joint name="y_attack_rotation" type="hinge" axis="0 0 1" range="-180.0 180.0"/>
        <inertial pos="0 0 0" quat="1 0 0 0" mass="1.25706" diaginertia="126.98281568 126.98281568 0.0495159"/>
        <!-- Yellow attacker Aluminum Rod -->
        <geom name="y_attack_rod" type="cylinder" size="0.78 55.08625" pos="0 0 0" rgba="0.8 0.8 0.8 1"/>
        <!-- Yellow Handle -->
        <body name="y_attack_rod_handle" pos="0 0 52.069" euler="180 0 0">
          <geom type="mesh" mesh="handle" mass='0.01' rgba='0.7 0.7 0.0 1' />
        </body>
        <!-- Rubber Pad-->
        <body name="y_attack_rod_r_rubber" pos="0 0 -27.816" euler="0 0 90">
          <inertial pos="0 0 0" quat="1 0 0 0" mass="0.05" diaginertia="0.00179 0.00179 0.00306"/>
          <geom name="y_attack_rod_r_rubber" type="cylinder" friction="0.1" size="1.5875 1.27" pos="0 0 0" rgba="0.0 0.0 0.0 1"/>
        </body>
        <body name="y_attack_rod_l_rubber" pos="0 0 14.249" euler="0 0 90">
          <inertial pos="0 0 0" quat="1 0 0 0" mass="0.05" diaginertia="0.00179 0.00179 0.00306"/>
          <geom name="y_attack_rod_l_rubber" type="cylinder" friction="0.1" size="1.5875 1.27" pos="0 0 0" rgba="0.0 0.0 0.0 1"/>
        </body>
        <!-- 3 Yellow Players -->
        <body name="y_attack_guy1" pos="1.49 -0.05 -24.959" euler="180 -90 0">
          <geom type="sdf" name="y_attack_guy1" mesh="guy" mass='0.07' rgba="0.95 0.95 0.0 1">
              <plugin instance="sdf2"/>
          </geom>
        </body>
        <body name="y_attack_guy2" pos="1.49 -0.05 -6.784" euler="180 -90 0">
          <geom type="sdf" name="y_attack_guy2" mesh="guy" mass='0.07' rgba="0.95 0.95 0.0 1">
              <plugin instance="sdf2"/>
          </geom>
        </body>
        <body name="y_attack_guy3" pos="1.49 -0.05 11.391" euler="180 -90 0">
          <geom type="sdf" name="y_attack_guy3" mesh="guy" mass='0.07' rgba="0.95 0.95 0.0 1">
              <plugin instance="sdf2"/>
          </geom>
        </body>
      </body>

    <!-- Black Player--><!-- Black Player--><!-- Black Player--><!-- Black Player-->
      <!-- Black goalie Rod-->
      <body name="b_goal_rod" pos="-6.902 52.5 7.75" euler="0 -90 180">
        <joint name="b_goal_linear" type="slide" axis="0 0 1" range="-300 300"/>
        <joint name="b_goal_rotation" type="hinge" axis="0 0 1" range="-180.0 180.0"/>
        <inertial pos="0 0 0" mass="1.20268" diaginertia="111.19898539 111.2074505 0.05583827"/>
        <!-- Black goalkeeper Aluminum Rod -->
        <geom name="b_goal_rod" type="cylinder" size="0.78 52.7" pos="0 0 0" rgba="0.8 0.8 0.8 1"/>
        <!-- Black Handle -->
        <body name="b_goal_rod_handle" pos="0 0 50.5" euler="180 0 0">
          <geom type="mesh" mesh="handle" mass='0.01' rgba='0.1 0.1 0.1 1' />
        </body>
        <!-- Rubber Pad -->
        <body name="b_goal_rod_r_rubber" pos="0 0 -30.435" euler="0 0 90">
          <inertial pos="0 0 0" quat="1 0 0 0" mass="0.05" diaginertia="0.00179 0.00179 0.00306"/>
          <geom name="b_goal_rod_r_rubber" type="cylinder" friction="0.1" size="1.5875 1.27" pos="0 0 0" rgba="0.0 0.0 0.0 1"/>
        </body>
        <body name="b_goal_rod_l_rubber" pos="0 0 16.63" euler="0 0 90">
          <inertial pos="0 0 0" quat="1 0 0 0" mass="0.05" diaginertia="0.00179 0.00179 0.00306"/>
          <geom name="b_goal_rod_l_rubber" type="cylinder" friction="0.1" size="1.5875 1.27" pos="0 0 0" rgba="0.0 0.0 0.0 1"/>
        </body>
        <!-- 3 Black Players -->
        <body name="b_goal_guy1" pos="1.49 -0.05 -27.578" euler="180 -90 0">
            <geom type="sdf" name="b_goal_guy1" mesh="guy" mass='0.07' rgba="0.05 0.05 0.05 1">
                <plugin instance="sdf2"/>
            </geom>
        </body>
        <body name="b_goal_guy2" pos="1.49 -0.05 -6.902" euler="180 -90 0">
            <geom type="sdf" name="b_goal_guy2" mesh="guy" mass='0.07' rgba="0.05 0.05 0.05 1">
                <plugin instance="sdf2"/>
            </geom>
        </body>
        <body name="b_goal_guy3" pos="1.49 -0.05 13.773" euler="180 -90 0">
            <geom type="sdf" name="b_goal_guy3" mesh="guy" mass='0.07' rgba="0.05 0.05 0.05 1">
                <plugin instance="sdf2"/>
            </geom>
        </body>
      </body>

      <!-- Black defender Rod-->
      <body name="b_def_rod" pos="-6.6715 37.5 7.75" euler="0 -90 180">
        <joint name="b_def_linear" type="slide" axis="0 0 1" range="-250 250"/>
        <joint name="b_def_rotation" type="hinge" axis="0 0 1" range="-180.0 180.0"/>
        <inertial pos="0 0 0" mass="1.40207" diaginertia="176.18752095 176.18752095 0.05522986"/>
        <!-- Black defender Aluminum Rod -->
        <geom name="b_def_rod" type="cylinder" size="0.78 61.4365" pos="0 0 0" rgba="0.8 0.8 0.8 1"/>
        <!-- Black Handle -->
        <body name="b_def_rod_handle" pos="0 0 58.644" euler="180 0 0">
          <geom type="mesh" mesh="handle" mass='0.01' rgba='0.1 0.1 0.1 1' />
        </body>
        <!-- Rubber Pad -->
        <body name="b_def_rod_r_rubber" pos="0 0 -21.466" euler="0 0 90">
          <inertial pos="0 0 0" quat="1 0 0 0" mass="0.05" diaginertia="0.00179 0.00179 0.00306"/>
          <geom name="b_def_rod_r_rubber" type="cylinder" friction="0.1" size="1.5875 1.27" pos="0 0 0" rgba="0.0 0.0 0.0 1"/>
        </body>
        <body name="b_def_rod_l_rubber" pos="0 0 8.124" euler="0 0 90">
          <inertial pos="0 0 0" quat="1 0 0 0" mass="0.05" diaginertia="0.00179 0.00179 0.00306"/>
          <geom name="b_def_rod_l_rubber" type="cylinder" friction="0.1" size="1.5875 1.27" pos="0 0 0" rgba="0.0 0.0 0.0 1"/>
        </body>
        <!-- 2 Black Players -->
        <body name="b_def_guy1" pos="1.49 -0.05 -18.609" euler="180 -90 0">
            <geom type="sdf" name="b_def_guy1" mesh="guy" mass='0.07' rgba="0.05 0.05 0.05 1">
                <plugin instance="sdf2"/>
            </geom>
        </body>
        <body name="b_def_guy2" pos="1.49 -0.05 5.266" euler="180 -90 0">
            <geom type="sdf" name="b_def_guy2" mesh="guy" mass='0.07' rgba="0.05 0.05 0.05 1">
                <plugin instance="sdf2"/>
            </geom>
        </body>
      </body>

      <!-- Black Midfield Rod-->
      <body name="b_mid_rod" pos="-6.887 7.5 7.75" euler="0 -90 180">
        <joint name="b_mid_linear" type="slide" axis="0 0 1" range="-500 500"/>
        <joint name="b_mid_rotation" type="hinge" axis="0 0 1" range="-180.0 180.0"/>
        <inertial pos="0 0 0" mass="1.1264" diaginertia="91.364224 91.364224 0.044368"/>
        <!-- Black Midfield Aluminum Rod -->
        <geom name="b_mid_rod" type="cylinder" size="0.78 49.365" pos="0 0 0" rgba="0.8 0.8 0.8 1"/>
        <!-- Black Handle -->
        <body name="b_mid_rod_handle" pos="0 0 46.34" euler="180 0 0">
          <geom type="mesh" mesh="handle" mass='0.01' rgba='0.1 0.1 0.1 1' />
        </body>
        <!-- Rubber Pad -->
        <body name="b_mid_rod_r_rubber" pos="0 0 -33.695" euler="0 0 90">
          <inertial pos="0 0 0" quat="1 0 0 0" mass="0.05" diaginertia="0.00179 0.00179 0.00306"/>
          <geom name="b_mid_rod_r_rubber" type="cylinder" friction="0.1" size="1.5875 1.27" pos="0 0 0" rgba="0.0 0.0 0.0 1"/>
        </body>
        <body name="b_mid_rod_l_rubber" pos="0 0 19.92" euler="0 0 90">
          <inertial pos="0 0 0" quat="1 0 0 0" mass="0.05" diaginertia="0.00179 0.00179 0.00306"/>
          <geom name="b_mid_rod_l_rubber" type="cylinder" friction="0.1" size="1.5875 1.27" pos="0 0 0" rgba="0.0 0.0 0.0 1"/>
        </body>
        <!-- 5 Players -->
        <body name="b_mid_guy1" pos="1.49 -0.05 -30.837" euler="180 -90 0">
            <geom type="sdf" name="b_mid_guy1" mesh="guy" mass="0.07"   rgba="0.05 0.05 0.05 1">
                <plugin instance="sdf2"/>
            </geom>
        </body>
        <body name="b_mid_guy2" pos="1.49 -0.05 -18.862" euler="180 -90 0">
            <geom type="sdf" name="b_mid_guy2" mesh="guy" mass="0.07"   rgba="0.05 0.05 0.05 1">
                <plugin instance="sdf2"/>
            </geom>
        </body>
        <body name="b_mid_guy3" pos="1.49 -0.05 -6.887" euler="180 -90 0">
            <geom type="sdf" name="b_mid_guy3" mesh="guy" mass="0.07"   rgba="0.05 0.05 0.05 1">
                <plugin instance="sdf2"/>
            </geom>
        </body>
        <body name="b_mid_guy4" pos="1.49 -0.05 5.088" euler="180 -90 0">
            <geom type="sdf" name="b_mid_guy4" mesh="guy" mass="0.07"   rgba="0.05 0.05 0.05 1">
                <plugin instance="sdf2"/>
            </geom>
        </body>
        <body name="b_mid_guy5" pos="1.49 -0.05 17.063" euler="180 -90 0">
            <geom type="sdf" name="b_mid_guy5" mesh="guy" mass="0.07"   rgba="0.05 0.05 0.05 1">
                <plugin instance="sdf2"/>
            </geom>
        </body>
      </body>

      <!-- Black attacker Rod-->
      <body name="b_attack_rod" pos="-6.784 -22.5 7.75" euler="0 -90 180">
        <joint name="b_attack_linear" type="slide" axis="0 0 1" range="-300 300"/>
        <joint name="b_attack_rotation" type="hinge" axis="0 0 1" range="-180.0 180.0"/>
        <inertial pos="0 0 0" quat="1 0 0 0" mass="1.25706" diaginertia="126.98281568 126.98281568 0.0495159"/>
        <!-- Black attacker Aluminum Rod -->
        <geom name="b_attack_rod" type="cylinder" size="0.78 55.08625" pos="0 0 0" rgba="0.8 0.8 0.8 1"/>
        <!-- Black Handle -->
        <body name="b_attack_rod_handle" pos="0 0 52.069" euler="180 0 0">
          <geom type="mesh" mesh="handle" mass='0.01' rgba='0.1 0.1 0.1 1' />
        </body>
        <!-- Rubber Pad -->
        <body name="b_attack_rod_r_rubber" pos="0 0 -27.816" euler="0 0 90">
          <inertial pos="0 0 0" quat="1 0 0 0" mass="0.05" diaginertia="0.00179 0.00179 0.00306"/>
          <geom name="b_attack_rod_r_rubber" type="cylinder" friction="0.1" size="1.5875 1.27" pos="0 0 0" rgba="0.0 0.0 0.0 1"/>
        </body>
        <body name="b_attack_rod_l_rubber" pos="0 0 14.249" euler="0 0 90">
          <inertial pos="0 0 0" quat="1 0 0 0" mass="0.05" diaginertia="0.00179 0.00179 0.00306"/>
          <geom name="b_attack_rod_l_rubber" type="cylinder" friction="0.1" size="1.5875 1.27" pos="0 0 0" rgba="0.0 0.0 0.0 1"/>
        </body>
        <!-- 3 Black Players -->
        <body name="b_attack_guy1" pos="1.49 -0.05 -24.959" euler="180 -90 0">
            <geom type="sdf" name="b_attack_guy1" mesh="guy" mass='0.07' rgba="0.05 0.05 0.05 1">
                <plugin instance="sdf2"/>
            </geom>
        </body>
        <body name="b_attack_guy2" pos="1.49 -0.05 -6.784" euler="180 -90 0">
            <geom type="sdf" name="b_attack_guy2" mesh="guy" mass='0.07' rgba="0.05 0.05 0.05 1">
                <plugin instance="sdf2"/>
            </geom>
        </body>
        <body name="b_attack_guy3" pos="1.49 -0.05 11.391" euler="180 -90 0">
            <geom type="sdf" name="b_attack_guy3" mesh="guy" mass='0.07' rgba="0.05 0.05 0.05 1">
                <plugin instance="sdf2"/>
            </geom>
        </body>
      </body>


      <!-- MATCH BALL-->
      <body name="ball" pos="0 -4 1.705">
        <joint name="ball_x" type="slide" axis="1 0 0"  frictionloss="20"/>
        <joint name="ball_y" type="slide" axis="0 1 0" frictionloss="20"/>
        <geom name="ball" type="sphere" size="1.73355" mass="0.1" rgba="0.8 0.3 0.5 1"
              friction="0.01 0.1 10"  />
      </body>
  
    </worldbody>
  

    <!-- exclude the contact between the rods and the table -->
    <contact>
      <exclude body1="y_goal_rod" body2="table"/>
      <exclude body1="y_def_rod" body2="table"/>
      <exclude body1="y_mid_rod" body2="table"/>
      <exclude body1="y_attack_rod" body2="table"/>

      <exclude body1="b_goal_rod" body2="table"/>
      <exclude body1="b_def_rod" body2="table"/>
      <exclude body1="b_mid_rod" body2="table"/>
      <exclude body1="b_attack_rod" body2="table"/>

      <exclude body1="y_goal_rod_handle" body2="table"/>
      <exclude body1="y_def_rod_handle" body2="table"/>
      <exclude body1="y_mid_rod_handle" body2="table"/>
      <exclude body1="y_attack_rod_handle" body2="table"/>

      <exclude body1="b_goal_rod_handle" body2="table"/>
      <exclude body1="b_def_rod_handle" body2="table"/>
      <exclude body1="b_mid_rod_handle" body2="table"/>
      <exclude body1="b_attack_rod_handle" body2="table"/>

      <exclude body1="table_side_rubber_y_goal_r" body2="y_goal_rod"/>
      <exclude body1="table_side_rubber_y_goal_l" body2="y_goal_rod"/>
      <exclude body1="table_side_rubber_y_def_r" body2="y_def_rod"/>
      <exclude body1="table_side_rubber_y_def_l" body2="y_def_rod"/>
      <exclude body1="table_side_rubber_y_mid_r" body2="y_mid_rod"/>
      <exclude body1="table_side_rubber_y_mid_l" body2="y_mid_rod"/>
      <exclude body1="table_side_rubber_y_attack_r" body2="y_attack_rod"/>
      <exclude body1="table_side_rubber_y_attack_l" body2="y_attack_rod"/>

      <exclude body1="table_side_rubber_b_goal_r" body2="b_goal_rod"/>
      <exclude body1="table_side_rubber_b_goal_l" body2="b_goal_rod"/>
      <exclude body1="table_side_rubber_b_def_r" body2="b_def_rod"/>
      <exclude body1="table_side_rubber_b_def_l" body2="b_def_rod"/>
      <exclude body1="table_side_rubber_b_mid_r" body2="b_mid_rod"/>
      <exclude body1="table_side_rubber_b_mid_l" body2="b_mid_rod"/>
      <exclude body1="table_side_rubber_b_attack_r" body2="b_attack_rod"/>
      <exclude body1="table_side_rubber_b_attack_l" body2="b_attack_rod"/>
    </contact>
  

  <!-- Adjust the controller parameters (e.g., kp, kv) to replicate the simulated motion in the real-world environment, as physical dynamics may differ -->    
  <actuator>
      <position name="y_goal_linear" joint="y_goal_linear" ctrlrange="-10.0 10.0" kp="20000" kv="300" /> 
      <position name="y_goal_rotation" joint="y_goal_rotation" ctrlrange="-2.5 2.5" kp="70000" kv="1000" />
      <position name="y_def_linear" joint="y_def_linear" ctrlrange="-20.0 20.0" kp="10000" kv="200" /> 
      <position name="y_def_rotation" joint="y_def_rotation" ctrlrange="-2.5 2.5" kp="40000" kv="500" />
      <position name="y_mid_linear" joint="y_mid_linear" ctrlrange="-7.0 7.0" kp="40000" kv="500" /> 
      <position name="y_mid_rotation" joint="y_mid_rotation" ctrlrange="-2.5 2.5" kp="150000" kv="2000" />
      <position name="y_attack_linear" joint="y_attack_linear" ctrlrange="-12.0 12.0" kp="20000" kv="300" /> 
      <position name="y_attack_rotation" joint="y_attack_rotation" ctrlrange="-2.5 2.5" kp="70000" kv="1000" />
    
      <position name="b_goal_linear" joint="b_goal_linear" ctrlrange="-10.0 10.0" kp="20000" kv="300" />  
      <position name="b_goal_rotation" joint="b_goal_rotation" ctrlrange="-2.5 2.5" kp="70000" kv="1000" />
      <position name="b_def_linear" joint="b_def_linear" ctrlrange="-20.0 20.0" kp="10000" kv="200" /> 
      <position name="b_def_rotation" joint="b_def_rotation" ctrlrange="-2.5 2.5" kp="40000" kv="500" />
      <position name="b_mid_linear" joint="b_mid_linear" ctrlrange="-7.0 7.0" kp="40000" kv="500" /> 
      <position name="b_mid_rotation" joint="b_mid_rotation" ctrlrange="-2.5 2.5" kp="150000" kv="2000" />
      <position name="b_attack_linear" joint="b_attack_linear" ctrlrange="-12.0 12.0" kp="20000" kv="300" /> 
      <position name="b_attack_rotation" joint="b_attack_rotation" ctrlrange="-2.5 2.5" kp="70000" kv="1000" />
    </actuator>

  </mujoco>
  