<mujoco>
    <default>
      <default class="visual">
        <geom group="2" type="mesh" contype="0" conaffinity="0"/>
      </default>
      <default class="collision">
        <geom group="3" type="mesh"/>
      </default>
    </default>
  
    <extension>
      <plugin plugin="mujoco.sdf.sdflib">
        <instance name="sdf1">
          <config key="aabb" value="1"/>
        </instance>
      </plugin>
      <plugin plugin="mujoco.sdf.sdflib">
        <instance name="sdf2">
          <config key="aabb" value="0"/>
        </instance>
      </plugin>
    </extension>
  
    <asset>
      <!-- <texture name="ball_pattern" type="2d" file="ball_texture.jpg"/>
      <material name="pink_ball" texture="ball_pattern"/> -->
  
      <mesh name="table" file="asset/foosball_table/foosball_table_nofloor.obj">
        <plugin instance="sdf1"/>
      </mesh>

      <mesh name="guy" file="asset/foosman/scale_Tornado_Foosman.obj">
          <plugin instance="sdf2"/>
      </mesh>

    </asset>
  
    <option sdf_iterations="20" sdf_initpoints="40"/>
  
    <visual>
      <map force="1000"/>
    </visual>
  
    <!-- <default>
      <geom solref="0.01 1" solimp=".95 .99 .0001" friction="0.5"/>
    </default> -->
  
    <include file="foosball_scene.xml"/>

    <worldbody>
      <!-- TABLE-->
      <body name="table" euler="0 0 0" pos="0 0 0">
        <inertial pos="-0.000002765 0.000000008 1.053097" quat="1 0 0 0" mass="54.82168339136806" 
                  diaginertia="7049.04002 1362.00289 8372.77663"/>
        <geom type="sdf" name="table" mesh="table" rgba='0.5 0.5 0.5 1'>
          <plugin instance="sdf1"/>
        </geom>
      </body>

    <!-- Yellow Player-->
      <!-- Yellow goalkeeper Rod-->
      <body name="y_goal_rod" pos="0 -10.5 1.5" euler="0 90 0">
        <joint name="y_goal_linear" type="slide" axis="0 0 1" range="-300 300"/>
        <joint name="y_goal_rotation" type="hinge" axis="0 0 1" range="-180.0 180.0"/>
        <inertial pos="0 0 0" quat="1 0 0 0" mass="0.2" 
                  diaginertia="4.267930716666667 4.267930716666667 0.0025281"/>
        <geom name="y_goal_rod" type="cylinder" size="0.159 11" pos="0 0 0" rgba="0.9 0.9 0.9 1"/>
        <!-- Rubbur Pad-->
        <body name="y_goal_rod_r_rubber" pos="0 0 -3.1" euler="0 0 90">
          <inertial pos="0 0 0" quat="1 0 0 0" mass="0.05" 
          diaginertia="0.00179 0.00179 0.00306"/>
          <geom name="y_goal_rod_r_rubber" type="cylinder" size="0.35 0.25" pos="0 0 0" rgba="0.0 0.0 0.0 1"/>
        </body>
        <body name="y_goal_rod_l_rubber" pos="0 0 3.1" euler="0 0 90">
          <inertial pos="0 0 0" quat="1 0 0 0" mass="0.05" 
          diaginertia="0.00179 0.00179 0.00306"/>
          <geom name="y_goal_rod_l_rubber" type="cylinder" size="0.35 0.25" pos="0 0 0" rgba="0.0 0.0 0.0 1"/>
        </body>

        <!-- 3 Yellow Players -->
        <body name="y_goal_guy1" pos="0.3 0 -2.5" euler="0 0 90">
          <inertial pos="0.004145 0.080444 -0.000002" quat="1 0 0 0" mass="0.38576930594052466" 
                    diaginertia="0.132288404 0.017566716 0.132398588"/>
          <geom type="sdf" name="y_goal_guy1" mesh="guy" mass='0.05' rgba="0.95 0.95 0.0 1">
              <plugin instance="sdf2"/>
          </geom>
        </body>
        <body name="y_goal_guy2" pos="0.3 0 0" euler="0 0 90">
          <inertial pos="0.004145 0.080444 -0.000002" quat="1 0 0 0" mass="0.38576930594052466" 
                    diaginertia="0.132288404 0.017566716 0.132398588"/>
          <geom type="sdf" name="y_goal_guy2" mesh="guy" mass='0.05' rgba="0.95 0.95 0.0 1">
              <plugin instance="sdf2"/>
          </geom>
        </body>
        <body name="y_goal_guy3" pos="0.3 0 2.5" euler="0 0 90">
          <inertial pos="0.004145 0.080444 -0.000002" quat="1 0 0 0" mass="0.38576930594052466" 
                    diaginertia="0.132288404 0.017566716 0.132398588"/>
          <geom type="sdf" name="y_goal_guy3" mesh="guy" mass='0.05' rgba="0.95 0.95 0.0 1">
              <plugin instance="sdf2"/>
          </geom>
        </body>
      </body>
    
      <!-- Yellow defender Rod-->
      <body name="y_def_rod" pos="0 -7.5 1.5" euler="0 90 0">
        <joint name="y_def_linear" type="slide" axis="0 0 1" range="-250 250"/>
        <joint name="y_def_rotation" type="hinge" axis="0 0 1" range="-180.0 180.0"/>
        <inertial pos="0 0 0" quat="1 0 0 0" mass="0.2" 
                  diaginertia="4.267930716666667 4.267930716666667 0.0025281"/>
        <geom name="y_def_rod" type="cylinder" size="0.159 11" pos="0 0 0" rgba="0.9 0.9 0.9 1"/>
        <!-- Rubbur Pad-->
        <body name="y_def_rod_r_rubber" pos="0 0 -2.6" euler="0 0 90">
          <inertial pos="0 0 0" quat="1 0 0 0" mass="0.05" 
          diaginertia="0.00179 0.00179 0.00306"/>
          <geom name="y_def_rod_r_rubber" type="cylinder" size="0.35 0.25" pos="0 0 0" rgba="0.0 0.0 0.0 1"/>
        </body>
        <body name="y_def_rod_l_rubber" pos="0 0 2.6" euler="0 0 90">
          <inertial pos="0 0 0" quat="1 0 0 0" mass="0.05" 
          diaginertia="0.00179 0.00179 0.00306"/>
          <geom name="y_def_rod_l_rubber" type="cylinder" size="0.35 0.25" pos="0 0 0" rgba="0.0 0.0 0.0 1"/>
        </body>

        <!-- 2 Yellow Players -->
        <body name="y_def_guy1" pos="0.3 0 -2.0" euler="0 0 90">
          <inertial pos="0.004145 0.080444 -0.000002" quat="1 0 0 0" mass="0.38576930594052466" 
                    diaginertia="0.132288404 0.017566716 0.132398588"/>
          <geom type="sdf" name="y_def_guy1" mesh="guy" mass='0.05' rgba="0.95 0.95 0.0 1">
              <plugin instance="sdf2"/>
          </geom>
        </body>
        <body name="y_def_guy2" pos="0.3 0 2.0" euler="0 0 90">
          <inertial pos="0.004145 0.080444 -0.000002" quat="1 0 0 0" mass="0.38576930594052466" 
                    diaginertia="0.132288404 0.017566716 0.132398588"/>
          <geom type="sdf" name="y_def_guy2" mesh="guy" mass='0.05' rgba="0.95 0.95 0.0 1">
              <plugin instance="sdf2"/>
          </geom>
        </body>
      </body>

      <!-- Yellow Midfield Rod-->
      <body name="y_mid_rod" pos="0 -1.5 1.5" euler="0 90 0">
        <joint name="y_mid_linear" type="slide" axis="0 0 1" range="-500 500"/>
        <joint name="y_mid_rotation" type="hinge" axis="0 0 1" range="-180.0 180.0"/>
        <inertial pos="0 0 0" quat="1 0 0 0" mass="0.2" 
                  diaginertia="4.267930716666667 4.267930716666667 0.0025281"/>
        <geom name="y_mid_rod" type="cylinder" size="0.159 10" pos="0 0 0" rgba="0.9 0.9 0.9 1"/>
        <!-- Rubbur Pad-->
        <body name="y_mid_rod_r_rubber" pos="0 0 -3.6" euler="0 0 90">
          <inertial pos="0 0 0" quat="1 0 0 0" mass="0.05" 
          diaginertia="0.00179 0.00179 0.00306"/>
          <geom name="y_mid_rod_r_rubber" type="cylinder" size="0.35 0.25" pos="0 0 0" rgba="0.0 0.0 0.0 1"/>
        </body>
        <body name="y_mid_rod_l_rubber" pos="0 0 3.6" euler="0 0 90">
          <inertial pos="0 0 0" quat="1 0 0 0" mass="0.05" 
          diaginertia="0.00179 0.00179 0.00306"/>
          <geom name="y_mid_rod_l_rubber" type="cylinder" size="0.35 0.25" pos="0 0 0" rgba="0.0 0.0 0.0 1"/>
        </body>

        <!-- Yellow Players -->
        <body name="y_mid_guy1" pos="0.3 0 -3" euler="0 0 90">
          <inertial pos="0.004145 0.080444 -0.000002" quat="1 0 0 0" mass="0.38576930594052466" 
                    diaginertia="0.132288404 0.017566716 0.132398588"/>
          <geom type="sdf" name="y_mid_guy1" mesh="guy" mass='0.05' rgba="0.95 0.95 0.0 1">
              <plugin instance="sdf2"/>
          </geom>
        </body>
        <body name="y_mid_guy2" pos="0.3 0 -1.5" euler="0 0 90">
          <inertial pos="0.004145 0.080444 -0.000002" quat="1 0 0 0" mass="0.38576930594052466" 
                    diaginertia="0.132288404 0.017566716 0.132398588"/>
          <geom type="sdf" name="y_mid_guy2" mesh="guy" mass='0.05' rgba="0.95 0.95 0.0 1">
              <plugin instance="sdf2"/>
          </geom>
        </body>
        <body name="y_mid_guy3" pos="0.3 0 0" euler="0 0 90">
          <inertial pos="0.004145 0.080444 -0.000002" quat="1 0 0 0" mass="0.38576930594052466" 
                    diaginertia="0.132288404 0.017566716 0.132398588"/>
          <geom type="sdf" name="y_mid_guy3" mesh="guy" mass='0.05' rgba="0.95 0.95 0.0 1">
              <plugin instance="sdf2"/>
          </geom>
        </body>
        <body name="y_mid_guy4" pos="0.3 0 1.5" euler="0 0 90">
          <inertial pos="0.004145 0.080444 -0.000002" quat="1 0 0 0" mass="0.38576930594052466" 
                    diaginertia="0.132288404 0.017566716 0.132398588"/>
          <geom type="sdf" name="y_mid_guy4" mesh="guy" mass='0.05' rgba="0.95 0.95 0.0 1">
              <plugin instance="sdf2"/>
          </geom>
        </body>
        <body name="y_mid_guy5" pos="0.3 0 3" euler="0 0 90">
          <inertial pos="0.004145 0.080444 -0.000002" quat="1 0 0 0" mass="0.38576930594052466" 
                    diaginertia="0.132288404 0.017566716 0.132398588"/>
          <geom type="sdf" name="y_mid_guy5" mesh="guy" mass='0.05' rgba="0.95 0.95 0.0 1">
              <plugin instance="sdf2"/>
          </geom>
        </body>
      </body>

      <!-- Yellow attacker Rod-->
      <body name="y_attack_rod" pos="0 4.5 1.5" euler="0 90 0">
        <joint name="y_attack_linear" type="slide" axis="0 0 1" range="-300 300"/>
        <joint name="y_attack_rotation" type="hinge" axis="0 0 1" range="-180.0 180.0"/>
        <inertial pos="0 0 0" quat="1 0 0 0" mass="0.2" 
                  diaginertia="4.267930716666667 4.267930716666667 0.0025281"/>
        <geom name="y_attack_rod" type="cylinder" size="0.159 11" pos="0 0 0" rgba="0.9 0.9 0.9 1"/>
        <!-- Rubbur Pad-->
        <body name="y_attack_rod_r_rubber" pos="0 0 -3.1" euler="0 0 90">
          <inertial pos="0 0 0" quat="1 0 0 0" mass="0.05" 
          diaginertia="0.00179 0.00179 0.00306"/>
          <geom name="y_attack_rod_r_rubber" type="cylinder" size="0.35 0.25" pos="0 0 0" rgba="0.0 0.0 0.0 1"/>
        </body>
        <body name="y_attack_rod_l_rubber" pos="0 0 3.1" euler="0 0 90">
          <inertial pos="0 0 0" quat="1 0 0 0" mass="0.05" 
          diaginertia="0.00179 0.00179 0.00306"/>
          <geom name="y_attack_rod_l_rubber" type="cylinder" size="0.35 0.25" pos="0 0 0" rgba="0.0 0.0 0.0 1"/>
        </body>

        <!-- 3 Yellow Players -->
        <body name="y_attack_guy1" pos="0.3 0 -2.5" euler="0 0 90">
          <inertial pos="0.004145 0.080444 -0.000002" quat="1 0 0 0" mass="0.38576930594052466" 
                    diaginertia="0.132288404 0.017566716 0.132398588"/>
          <geom type="sdf" name="y_attack_guy1" mesh="guy" mass='0.05' rgba="0.95 0.95 0.0 1">
              <plugin instance="sdf2"/>
          </geom>
        </body>
        <body name="y_attack_guy2" pos="0.3 0 0" euler="0 0 90">
          <inertial pos="0.004145 0.080444 -0.000002" quat="1 0 0 0" mass="0.38576930594052466" 
                    diaginertia="0.132288404 0.017566716 0.132398588"/>
          <geom type="sdf" name="y_attack_guy2" mesh="guy" mass='0.05' rgba="0.95 0.95 0.0 1">
              <plugin instance="sdf2"/>
          </geom>
        </body>
        <body name="y_attack_guy3" pos="0.3 0 2.5" euler="0 0 90">
          <inertial pos="0.004145 0.080444 -0.000002" quat="1 0 0 0" mass="0.38576930594052466" 
                    diaginertia="0.132288404 0.017566716 0.132398588"/>
          <geom type="sdf" name="y_attack_guy3" mesh="guy" mass='0.05' rgba="0.95 0.95 0.0 1">
              <plugin instance="sdf2"/>
          </geom>
        </body>
      </body>

      <!-- Black Player-->
      <!-- Black goalkeeper Rod-->
      <body name="b_goal_rod" pos="0 10.5 1.5" euler="0 -90 180">
        <joint name="b_goal_linear" type="slide" axis="0 0 1" range="-300 300"/>
        <joint name="b_goal_rotation" type="hinge" axis="0 0 1" range="-180.0 180.0"/>
        <inertial pos="0 0 0" quat="1 0 0 0" mass="0.2" 
                  diaginertia="4.267930716666667 4.267930716666667 0.0025281"/>
        <geom name="b_goal_rod" type="cylinder" size="0.159 11" pos="0 0 0" rgba="0.9 0.9 0.9 1"/>
        <!-- Rubber Pad -->
        <body name="b_goal_rod_r_rubber" pos="0 0 -3.1" euler="0 0 90">
          <inertial pos="0 0 0" quat="1 0 0 0" mass="0.05" 
          diaginertia="0.00179 0.00179 0.00306"/>
          <geom name="b_goal_rod_r_rubber" type="cylinder" size="0.35 0.25" pos="0 0 0" rgba="0.0 0.0 0.0 1"/>
        </body>
        <body name="b_goal_rod_l_rubber" pos="0 0 3.1" euler="0 0 90">
          <inertial pos="0 0 0" quat="1 0 0 0" mass="0.05" 
          diaginertia="0.00179 0.00179 0.00306"/>
          <geom name="b_goal_rod_l_rubber" type="cylinder" size="0.35 0.25" pos="0 0 0" rgba="0.0 0.0 0.0 1"/>
        </body>

        <!-- 3 Black Players -->
        <body name="b_goal_guy1" pos="0.3 0 -2.5" euler="0 0 90">
            <inertial pos="0.004145 0.080444 -0.000002" quat="1 0 0 0" mass="0.38576930594052466" 
                      diaginertia="0.132288404 0.017566716 0.132398588"/>
            <geom type="sdf" name="b_goal_guy1" mesh="guy" mass='0.05' rgba="0.05 0.05 0.05 1">
                <plugin instance="sdf2"/>
            </geom>
        </body>
        <body name="b_goal_guy2" pos="0.3 0 0" euler="0 0 90">
            <inertial pos="0.004145 0.080444 -0.000002" quat="1 0 0 0" mass="0.38576930594052466" 
                      diaginertia="0.132288404 0.017566716 0.132398588"/>
            <geom type="sdf" name="b_goal_guy2" mesh="guy" mass='0.05' rgba="0.05 0.05 0.05 1">
                <plugin instance="sdf2"/>
            </geom>
        </body>
        <body name="b_goal_guy3" pos="0.3 0 2.5" euler="0 0 90">
            <inertial pos="0.004145 0.080444 -0.000002" quat="1 0 0 0" mass="0.38576930594052466" 
                      diaginertia="0.132288404 0.017566716 0.132398588"/>
            <geom type="sdf" name="b_goal_guy3" mesh="guy" mass='0.05' rgba="0.05 0.05 0.05 1">
                <plugin instance="sdf2"/>
            </geom>
        </body>
      </body>

      <!-- Black defender Rod-->
      <body name="b_def_rod" pos="0 7.5 1.5" euler="0 -90 180">
        <joint name="b_def_linear" type="slide" axis="0 0 1" range="-250 250"/>
        <joint name="b_def_rotation" type="hinge" axis="0 0 1" range="-180.0 180.0"/>
        <inertial pos="0 0 0" quat="1 0 0 0" mass="0.2" 
                  diaginertia="4.267930716666667 4.267930716666667 0.0025281"/>
        <geom name="b_def_rod" type="cylinder" size="0.159 11" pos="0 0 0" rgba="0.9 0.9 0.9 1"/>
        <!-- Rubber Pad -->
        <body name="b_def_rod_r_rubber" pos="0 0 -2.6" euler="0 0 90">
          <inertial pos="0 0 0" quat="1 0 0 0" mass="0.05" 
          diaginertia="0.00179 0.00179 0.00306"/>
          <geom name="b_def_rod_r_rubber" type="cylinder" size="0.35 0.25" pos="0 0 0" rgba="0.0 0.0 0.0 1"/>
        </body>
        <body name="b_def_rod_l_rubber" pos="0 0 2.6" euler="0 0 90">
          <inertial pos="0 0 0" quat="1 0 0 0" mass="0.05" 
          diaginertia="0.00179 0.00179 0.00306"/>
          <geom name="b_def_rod_l_rubber" type="cylinder" size="0.35 0.25" pos="0 0 0" rgba="0.0 0.0 0.0 1"/>
        </body>

        <!-- 2 Black Players -->
        <body name="b_def_guy1" pos="0.3 0 -2.0" euler="0 0 90">
            <inertial pos="0.004145 0.080444 -0.000002" quat="1 0 0 0" mass="0.38576930594052466" 
                      diaginertia="0.132288404 0.017566716 0.132398588"/>
            <geom type="sdf" name="b_def_guy1" mesh="guy" mass='0.05' rgba="0.05 0.05 0.05 1">
                <plugin instance="sdf2"/>
            </geom>
        </body>
        <body name="b_def_guy2" pos="0.3 0 2.0" euler="0 0 90">
            <inertial pos="0.004145 0.080444 -0.000002" quat="1 0 0 0" mass="0.38576930594052466" 
                      diaginertia="0.132288404 0.017566716 0.132398588"/>
            <geom type="sdf" name="b_def_guy2" mesh="guy" mass='0.05' rgba="0.05 0.05 0.05 1">
                <plugin instance="sdf2"/>
            </geom>
        </body>
      </body>

      <!-- Black Midfield Rod-->
      <body name="b_mid_rod" pos="0 1.5 1.5" euler="0 -90 180">
        <joint name="b_mid_linear" type="slide" axis="0 0 1" range="-500 500"/>
        <joint name="b_mid_rotation" type="hinge" axis="0 0 1" range="-180.0 180.0"/>
        <inertial pos="0 0 0" quat="1 0 0 0" mass="0.2" 
                  diaginertia="4.267930716666667 4.267930716666667 0.0025281"/>
        <geom name="b_mid_rod" type="cylinder" size="0.159 10" pos="0 0 0" rgba="0.9 0.9 0.9 1"/>
        <!-- Rubber Pad -->
        <body name="b_mid_rod_r_rubber" pos="0 0 -3.6" euler="0 0 90">
          <inertial pos="0 0 0" quat="1 0 0 0" mass="0.05" 
          diaginertia="0.00179 0.00179 0.00306"/>
          <geom name="b_mid_rod_r_rubber" type="cylinder" size="0.35 0.25" pos="0 0 0" rgba="0.0 0.0 0.0 1"/>
        </body>
        <body name="b_mid_rod_l_rubber" pos="0 0 3.6" euler="0 0 90">
          <inertial pos="0 0 0" quat="1 0 0 0" mass="0.05" 
          diaginertia="0.00179 0.00179 0.00306"/>
          <geom name="b_mid_rod_l_rubber" type="cylinder" size="0.35 0.25" pos="0 0 0" rgba="0.0 0.0 0.0 1"/>
        </body>

        <!-- 5 Players -->
        <body name="b_mid_guy1" pos="0.3 0 -3" euler="0 0 90">
            <inertial pos="0.004145 0.080444 -0.000002" quat="1 0 0 0" mass="0.38576930594052466" 
                      diaginertia="0.132288404 0.017566716 0.132398588"/>
            <geom type="sdf" name="b_mid_guy1" mesh="guy" mass='0.05' rgba="0.05 0.05 0.05 1">
                <plugin instance="sdf2"/>
            </geom>
        </body>
        <body name="b_mid_guy2" pos="0.3 0 -1.5" euler="0 0 90">
            <inertial pos="0.004145 0.080444 -0.000002" quat="1 0 0 0" mass="0.38576930594052466" 
                      diaginertia="0.132288404 0.017566716 0.132398588"/>
            <geom type="sdf" name="b_mid_guy2" mesh="guy" mass='0.05' rgba="0.05 0.05 0.05 1">
                <plugin instance="sdf2"/>
            </geom>
        </body>
        <body name="b_mid_guy3" pos="0.3 0 0" euler="0 0 90">
            <inertial pos="0.004145 0.080444 -0.000002" quat="1 0 0 0" mass="0.38576930594052466" 
                      diaginertia="0.132288404 0.017566716 0.132398588"/>
            <geom type="sdf" name="b_mid_guy3" mesh="guy" mass='0.05' rgba="0.05 0.05 0.05 1">
                <plugin instance="sdf2"/>
            </geom>
        </body>
        <body name="b_mid_guy4" pos="0.3 0 1.5" euler="0 0 90">
            <inertial pos="0.004145 0.080444 -0.000002" quat="1 0 0 0" mass="0.38576930594052466" 
                      diaginertia="0.132288404 0.017566716 0.132398588"/>
            <geom type="sdf" name="b_mid_guy4" mesh="guy" mass='0.05' rgba="0.05 0.05 0.05 1">
                <plugin instance="sdf2"/>
            </geom>
        </body>
        <body name="b_mid_guy5" pos="0.3 0 3" euler="0 0 90">
            <inertial pos="0.004145 0.080444 -0.000002" quat="1 0 0 0" mass="0.38576930594052466" 
                      diaginertia="0.132288404 0.017566716 0.132398588"/>
            <geom type="sdf" name="b_mid_guy5" mesh="guy" mass='0.05' rgba="0.05 0.05 0.05 1">
                <plugin instance="sdf2"/>
            </geom>
        </body>
      </body>

      <!-- Black attacker Rod-->
      <body name="b_attack_rod" pos="0 -4.5 1.5" euler="0 -90 180">
        <joint name="b_attack_linear" type="slide" axis="0 0 1" range="-300 300"/>
        <joint name="b_attack_rotation" type="hinge" axis="0 0 1" range="-180.0 180.0"/>
        <inertial pos="0 0 0" quat="1 0 0 0" mass="0.2" 
                  diaginertia="4.267930716666667 4.267930716666667 0.0025281"/>
        <geom name="b_attack_rod" type="cylinder" size="0.159 11" pos="0 0 0" rgba="0.9 0.9 0.9 1"/>
        <!-- Rubber Pad -->
        <body name="b_attack_rod_r_rubber" pos="0 0 -3.1" euler="0 0 90">
          <inertial pos="0 0 0" quat="1 0 0 0" mass="0.05" 
          diaginertia="0.00179 0.00179 0.00306"/>
          <geom name="b_attack_rod_r_rubber" type="cylinder" size="0.35 0.25" pos="0 0 0" rgba="0.0 0.0 0.0 1"/>
        </body>
        <body name="b_attack_rod_l_rubber" pos="0 0 3.1" euler="0 0 90">
          <inertial pos="0 0 0" quat="1 0 0 0" mass="0.05" 
          diaginertia="0.00179 0.00179 0.00306"/>
          <geom name="b_attack_rod_l_rubber" type="cylinder" size="0.35 0.25" pos="0 0 0" rgba="0.0 0.0 0.0 1"/>
        </body>

        <!-- 3 Black Players -->
        <body name="b_attack_guy1" pos="0.3 0 -2.5" euler="0 0 90">
            <inertial pos="0.004145 0.080444 -0.000002" quat="1 0 0 0" mass="0.38576930594052466" 
                      diaginertia="0.132288404 0.017566716 0.132398588"/>
            <geom type="sdf" name="b_attack_guy1" mesh="guy" mass='0.05' rgba="0.05 0.05 0.05 1">
                <plugin instance="sdf2"/>
            </geom>
        </body>
        <body name="b_attack_guy2" pos="0.3 0 0" euler="0 0 90">
            <inertial pos="0.004145 0.080444 -0.000002" quat="1 0 0 0" mass="0.38576930594052466" 
                      diaginertia="0.132288404 0.017566716 0.132398588"/>
            <geom type="sdf" name="b_attack_guy2" mesh="guy" mass='0.05' rgba="0.05 0.05 0.05 1">
                <plugin instance="sdf2"/>
            </geom>
        </body>
        <body name="b_attack_guy3" pos="0.3 0 2.5" euler="0 0 90">
            <inertial pos="0.004145 0.080444 -0.000002" quat="1 0 0 0" mass="0.38576930594052466" 
                      diaginertia="0.132288404 0.017566716 0.132398588"/>
            <geom type="sdf" name="b_attack_guy3" mesh="guy" mass='0.05' rgba="0.05 0.05 0.05 1">
                <plugin instance="sdf2"/>
            </geom>
        </body>
      </body>



      <!-- MATCH BALL-->
      <body name="ball" pos="0 0 0.5">
        <freejoint/>
        <!-- <geom type="sphere" size="0.5" rgba="1 1 1 1" mass="0.25" material="chess"/> -->
        <geom type="sphere" size="0.5" rgba="0.8 0.3 0.5 1" mass="4" 
              solref="0.02 1" solimp="0.95 0.95 0.001" friction="0.01"/>
      </body>
  
    </worldbody>
  


    <!-- exclude the contact between the rods and the table -->
    <contact>
      <exclude body1="y_goal_rod" body2="table"/>
      <exclude body1="y_def_rod" body2="table"/>
      <exclude body1="y_mid_rod" body2="table"/>
      <exclude body1="y_attack_rod" body2="table"/>

      <exclude body1="b_goal_rod" body2="table"/>
      <exclude body1="b_def_rod" body2="table"/>
      <exclude body1="b_mid_rod" body2="table"/>
      <exclude body1="b_attack_rod" body2="table"/>
    </contact>
  

  <!-- Adjust the controller parameters (e.g., kp, kv) to replicate the simulated motion in the real-world environment, as physical dynamics may differ -->    <actuator>
      <position name="y_goal_linear" joint="y_goal_linear" ctrlrange="-3.0 3.0" kp="2000" kv="100" />
      <position name="y_goal_rotation" joint="y_goal_rotation" ctrlrange="-2.5 2.5" kp="2000" kv="100" />
      <position name="y_def_linear" joint="y_def_linear" ctrlrange="-3.5 3.5" kp="2000" kv="100" />
      <position name="y_def_rotation" joint="y_def_rotation" ctrlrange="-2.5 2.5" kp="2000" kv="100" />
      <position name="y_mid_linear" joint="y_mid_linear" ctrlrange="-2.5 2.5" kp="2000" kv="100" />
      <position name="y_mid_rotation" joint="y_mid_rotation" ctrlrange="-2.5 2.5" kp="2000" kv="100" />
      <position name="y_attack_linear" joint="y_attack_linear" ctrlrange="-3.0 3.0" kp="2000" kv="100" />
      <position name="y_attack_rotation" joint="y_attack_rotation" ctrlrange="-2.5 2.5" kp="2000" kv="100" />
    
      <position name="b_goal_linear" joint="b_goal_linear" ctrlrange="-3.0 3.0" kp="2000" kv="100" />
      <position name="b_goal_rotation" joint="b_goal_rotation" ctrlrange="-2.5 2.5" kp="2000" kv="100" />
      <position name="b_def_linear" joint="b_def_linear" ctrlrange="-3.5 3.5" kp="2000" kv="100" />
      <position name="b_def_rotation" joint="b_def_rotation" ctrlrange="-2.5 2.5" kp="2000" kv="100" />
      <position name="b_mid_linear" joint="b_mid_linear" ctrlrange="-2.5 2.5" kp="2000" kv="100" />
      <position name="b_mid_rotation" joint="b_mid_rotation" ctrlrange="-2.5 2.5" kp="2000" kv="100" />
      <position name="b_attack_linear" joint="b_attack_linear" ctrlrange="-3.0 3.0" kp="2000" kv="100" />
      <position name="b_attack_rotation" joint="b_attack_rotation" ctrlrange="-2.5 2.5" kp="2000" kv="100" />
    </actuator>


  </mujoco>
  