<mujoco>
    <worldbody>
      <body name="rod3_A1" euler="0 90 0" pos="0 8.5 2.5">
        <inertial pos="0.301556161 0 0" quat="1 0 0 0" mass="0.9077230663009997" 
                    diaginertia="4.66694774 4.95478689 0.298935845"/>
        <joint name="lin_A1" type="slide" pos="0 0 0" axis="0 0 1" range="-300 300"/>
        <joint name="rev_A1" type="hinge" pos="0 0 0" axis="0 0 1" range="-60.0 60.0"/>
        <geom type="mesh" mesh="rod3_0" rgba='0.5 0.1 0.1 1'/>
        <geom type="mesh" mesh="rod3_1" rgba='0.5 0.1 0.1 1'/>
        <geom type="mesh" mesh="rod3_2" rgba='0.5 0.1 0.1 1'/>
        <geom type="mesh" mesh="rod3_3" rgba='0.5 0.1 0.1 1'/>
        <geom type="mesh" mesh="rod3_4" rgba='0.5 0.1 0.1 1'/>
        <geom type="mesh" mesh="rod3_5" rgba='0.5 0.1 0.1 1'/>
        <geom type="mesh" mesh="rod3_6" rgba='0.5 0.1 0.1 1'/>
        <geom type="mesh" mesh="rod3_7" rgba='0.5 0.1 0.1 1'/>
        <geom type="mesh" mesh="rod3_8" rgba='0.5 0.1 0.1 1'/>
        <geom type="mesh" mesh="rod3_9" rgba='0.5 0.1 0.1 1'/>
        <geom type="mesh" mesh="rod3_10" rgba='0.5 0.1 0.1 1'/>
        <geom type="mesh" mesh="rod3_11" rgba='0.5 0.1 0.1 1'/>
      </body>  
    </worldbody>
  
    <actuator>
      <position joint="lin_A1" ctrlrange="-1.0 1.0" kp="2000" kv="100" />
      <position joint="rev_A1" ctrlrange="-1.0 1.0" kp="2000" kv="100" />
    </actuator>
  
  </mujoco>
  